<?xml version="1.0" encoding="utf-8"?>
<!-- =================================================================================== -->
<!-- |    This document was autogenerated by xacro from eleven_base.xacro              | -->
<!-- |    EDITING THIS FILE BY HAND IS NOT RECOMMENDED                                 | -->
<!-- =================================================================================== -->
<robot name="eleven_robot" xmlns:xacro="http://ros.org/wiki/xacro">
  <material name="black">
    <color rgba="0.0 0.0 0.0 1.0"/>
  </material>
  <material name="light_black">
    <color rgba="0.64706 0.61961 0.58824 1"/>
  </material>
  <material name="blue">
    <color rgba="0.0 0.0 0.8 1.0"/>
  </material>
  <material name="green">
    <color rgba="0.0 0.8 0.0 1.0"/>
  </material>
  <material name="grey">
    <color rgba="0.2 0.2 0.2 1.0"/>
  </material>
  <material name="orange">
    <color rgba="1.0 0.423529411765 0.0392156862745 1.0"/>
  </material>
  <material name="brown">
    <color rgba="0.870588235294 0.811764705882 0.764705882353 1.0"/>
  </material>
  <material name="red">
    <color rgba="0.8 0.0 0.0 1.0"/>
  </material>
  <material name="white">
    <color rgba="1.0 1.0 1.0 1.0"/>
  </material>
  <material name="aluminum">
    <color rgba="0.5 0.5 0.5 1.0"/>
  </material>
  <link name="base_footprint"/>
  <joint name="base_fixed" type="fixed">
    <origin rpy="0 0 0" xyz="0 0 0.1"/>
    <parent link="base_footprint"/>
    <child link="base_link"/>
  </joint>
  <link name="base_link">
    <visual>
      <origin rpy="1.5707 0 -1.5707" xyz="0 0 -0.055"/>
      <geometry>
        <mesh filename="package://eleven_description/meshes/chessis.STL" scale="1 1 1"/>
      </geometry>
      <material name="green"/>
    </visual>
    <collision name="chessis_collision">
      <origin rpy="1.5707 0 -1.5707" xyz="0 0 -0.055"/>
      <geometry>
        <mesh filename="package://eleven_description/meshes/chessis.STL" scale="1 1 1"/>
      </geometry>
      <surface>
        <friction>
          <ode>
            <mu>0.1</mu>
            <mu2>0.1</mu2>
            <slip1>1.0</slip1>
            <slip2>1.0</slip2>
          </ode>
        </friction>
      </surface>
    </collision>
    <inertial>
      <mass value="10.0"/>
      <origin rpy=" 0 0 0" xyz="-0.15 0 0.1"/>
      <inertia ixx="0.166666666667" ixy="0" ixz="0" iyy="0.166666666667" iyz="0" izz="0.166666666667"/>
    </inertial>
  </link>
  <gazebo reference="base_link">
    <mu1>0.0001</mu1>
    <mu2>0.0001</mu2>
    <material>Gazebo/Red</material>
  </gazebo>
  <!-- <joint name="${prefix}_base_fixed" type="fixed">
            <insert_block name="origin"/>
            <parent link="${parent}"/>
            <child link="${prefix}_base_link"/>
        </joint>

        <link name="${prefix}_base_link"/> -->
  <joint name="left_wheel_joint" type="continuous">
    <!-- <origin xyz="0 0 0.06" rpy="0 0 0"/> -->
    <origin rpy="0 1.570795 1.570795" xyz="0 0.23 -0.02"/>
    <parent link="base_link"/>
    <child link="left_wheel_frame"/>
    <axis xyz="0 0 1"/>
    <limit effort="100" velocity="100.0"/>
    <dynamics damping="1.0" friction="1.0"/>
  </joint>
  <link name="left_wheel_frame">
    <visual>
      <origin rpy="0 -1.570796327 0" xyz="0 0 -0.03"/>
      <geometry>
        <mesh filename="package://anman_sensors/actuators/bldc_hover_65/meshes/bldc_hover_65.stl" scale="0.001 0.001 0.001"/>
      </geometry>
    </visual>
    <collision>
      <origin rpy="0 0 0" xyz="0 0 0"/>
      <geometry>
        <cylinder length="0.06" radius="0.08255"/>
        <!-- <mesh filename="package://anman_sensors/actuators/bldc_hover_65/meshes/bldc_hover_65.stl" scale="0.001 0.001 0.001"/> -->
      </geometry>
    </collision>
    <inertial>
      <origin rpy="0 0 0" xyz="0 0 0"/>
      <mass value="2.0"/>
      <inertia ixx="0.00400725125" ixy="0" ixz="0" iyy="0.00400725125" iyz="0" izz="0.0068145025"/>
    </inertial>
  </link>
  <gazebo reference="left_wheel_frame">
    <mu1>10.0</mu1>
    <mu2>10.0</mu2>
    <kp>1000000.0</kp>
    <kd>100.0</kd>
    <minDepth>0.001</minDepth>
    <maxVel>1.0</maxVel>
    <material>Gazebo/Orange</material>
  </gazebo>
  <transmission name="left_wheel_trans">
    <type>transmission_interface/SimpleTransmission</type>
    <joint name="left_wheel_joint">
      <!-- <hardwareInterface>hardware_interface/VelocityJointInterface</hardwareInterface> -->
      <hardwareInterface>hardware_interface/EffortJointInterface</hardwareInterface>
    </joint>
    <actuator name="left_wheel_motor">
      <!-- <hardwareInterface>hardware_interface/VelocityJointInterface</hardwareInterface> -->
      <hardwareInterface>hardware_interface/EffortJointInterface</hardwareInterface>
      <mechanicalReduction>1</mechanicalReduction>
    </actuator>
  </transmission>
  <!-- <joint name="${prefix}_base_fixed" type="fixed">
            <insert_block name="origin"/>
            <parent link="${parent}"/>
            <child link="${prefix}_base_link"/>
        </joint>

        <link name="${prefix}_base_link"/> -->
  <joint name="right_wheel_joint" type="continuous">
    <!-- <origin xyz="0 0 0.06" rpy="0 0 0"/> -->
    <origin rpy="0 1.570795 -1.570795" xyz="0 -0.23 -0.02"/>
    <parent link="base_link"/>
    <child link="right_wheel_frame"/>
    <axis xyz="0 0 -1"/>
    <limit effort="100" velocity="100.0"/>
    <dynamics damping="1.0" friction="1.0"/>
  </joint>
  <link name="right_wheel_frame">
    <visual>
      <origin rpy="0 -1.570796327 0" xyz="0 0 -0.03"/>
      <geometry>
        <mesh filename="package://anman_sensors/actuators/bldc_hover_65/meshes/bldc_hover_65.stl" scale="0.001 0.001 0.001"/>
      </geometry>
    </visual>
    <collision>
      <origin rpy="0 0 0" xyz="0 0 0"/>
      <geometry>
        <cylinder length="0.06" radius="0.08255"/>
        <!-- <mesh filename="package://anman_sensors/actuators/bldc_hover_65/meshes/bldc_hover_65.stl" scale="0.001 0.001 0.001"/> -->
      </geometry>
    </collision>
    <inertial>
      <origin rpy="0 0 0" xyz="0 0 0"/>
      <mass value="2.0"/>
      <inertia ixx="0.00400725125" ixy="0" ixz="0" iyy="0.00400725125" iyz="0" izz="0.0068145025"/>
    </inertial>
  </link>
  <gazebo reference="right_wheel_frame">
    <mu1>10.0</mu1>
    <mu2>10.0</mu2>
    <kp>1000000.0</kp>
    <kd>100.0</kd>
    <minDepth>0.001</minDepth>
    <maxVel>1.0</maxVel>
    <material>Gazebo/Orange</material>
  </gazebo>
  <transmission name="right_wheel_trans">
    <type>transmission_interface/SimpleTransmission</type>
    <joint name="right_wheel_joint">
      <!-- <hardwareInterface>hardware_interface/VelocityJointInterface</hardwareInterface> -->
      <hardwareInterface>hardware_interface/EffortJointInterface</hardwareInterface>
    </joint>
    <actuator name="right_wheel_motor">
      <!-- <hardwareInterface>hardware_interface/VelocityJointInterface</hardwareInterface> -->
      <hardwareInterface>hardware_interface/EffortJointInterface</hardwareInterface>
      <mechanicalReduction>1</mechanicalReduction>
    </actuator>
  </transmission>
  <joint name="imu_fixed" type="fixed">
    <origin rpy="0 0 1.570795" xyz="-0.25 0.08 0.1"/>
    <parent link="base_link"/>
    <child link="imu_link"/>
  </joint>
  <link name="imu_link">
    <visual>
      <origin rpy="0 0 0" xyz="0 0 0"/>
      <geometry>
        <box size="0.02 0.02 0.01"/>
      </geometry>
      <material name="blue"/>
    </visual>
    <collision>
      <origin rpy="0 0 0" xyz="0 0 0"/>
      <geometry>
        <box size="0.02 0.02 0.01"/>
      </geometry>
      <material name="blue"/>
    </collision>
    <inertia ixx="6.66666666667e-07" ixy="0" ixz="0" iyy="6.66666666667e-07" iyz="0" izz="6.66666666667e-07"/>
  </link>
  <gazebo reference="imu_link">
    <gravity>true</gravity>
    <sensor name="imu_sensor" type="imu">
      <pose>0 0 0 0 0 0</pose>
      <update_rate>10</update_rate>
      <plugin filename="libgazebo_ros_imu_sensor.so" name="imu_gazebo_plugin">
        <topicName>/imu</topicName>
        <bodyName>base_link</bodyName>
        <updateRateHZ>10.0</updateRateHZ>
        <gaussianNoise>0.0</gaussianNoise>
        <xyzOffset>0 0 0</xyzOffset>
        <rpyOffset>0 0 0</rpyOffset>
        <frameName>imu_link</frameName>
      </plugin>
    </sensor>
  </gazebo>
  <joint name="laser_base_fixed" type="fixed">
    <!-- <origin xyz="0 0 0" rpy="0 0 0"/> -->
    <origin rpy="0 0 0" xyz="0.15 0 0.2"/>
    <parent link="base_link"/>
    <child link="laser_base_link"/>
  </joint>
  <link name="laser_base_link">
    <visual>
      <origin rpy="0 0 0" xyz="0 0 0"/>
      <geometry>
        <mesh filename="package://anman_sensors/sensors/ydlidar/meshes/ydlidar_g4.dae"/>
      </geometry>
      <material name="light_black"/>
    </visual>
    <collision>
      <origin rpy="0 0 0" xyz="0 0 0.02"/>
      <geometry>
        <cylinder length="0.05" radius="0.040"/>
        <!-- <mesh filename="package://anman_sensors/sensors/ydlidar/meshes/ydlidar_g4.dae" /> -->
      </geometry>
    </collision>
    <inertial>
      <origin rpy="0 0 0" xyz="-0.00029774 0.0066667 0.00013047"/>
      <mass value="0.15717"/>
      <inertia ixx="6.7885E-05" ixy="-1.3987E-07" ixz="-8.1554E-07" iyy="0.00013173" iyz="-9.0932E-08" izz="7.1972E-05"/>
    </inertial>
  </link>
  <joint name="laser_fixed" type="fixed">
    <origin rpy="0 0 0" xyz="0 0 0.03172"/>
    <parent link="laser_base_link"/>
    <child link="laser_frame"/>
  </joint>
  <link name="laser_frame">
    <inertial>
      <origin rpy="0 0 0" xyz="-0.00036659 0.00064155 -0.00027052"/>
      <mass value="0.25482"/>
      <inertia ixx="8.9194E-05" ixy="1.8116E-07" ixz="3.6435E-08" iyy="0.00018279" iyz="2.423E-07" izz="0.00011103"/>
    </inertial>
  </link>
  <gazebo reference="laser_frame">
    <sensor name="laser_sensor" type="ray">
      <pose>0 0 0 0 0 0</pose>
      <visualize>False</visualize>
      <update_rate>20</update_rate>
      <ray>
        <scan>
          <horizontal>
            <!-- 180 deg -> 640 -->
            <!-- <samples>640</samples> -->
            <!-- <samples>1280</samples>  -->
            <samples>1280.3864204</samples>
            <resolution>1</resolution>
            <min_angle>-3.14159</min_angle>
            <max_angle>3.14159</max_angle>
          </horizontal>
        </scan>
        <range>
          <min>0.26</min>
          <max>12.0</max>
          <resolution>0.03</resolution>
        </range>
        <noise>
          <type>gaussian</type>
          <mean>0.0</mean>
          <stddev>0.01</stddev>
        </noise>
      </ray>
      <plugin filename="libgazebo_ros_laser.so" name="laser_gazebo_plugin">
        <topicName>/scan</topicName>
        <frameName>laser_frame</frameName>
      </plugin>
    </sensor>
  </gazebo>
  <gazebo>
    <plugin filename="libgazebo_ros_diff_drive.so" name="differential_drive_controller">
      <alwaysOn>true</alwaysOn>
      <updateRate>50</updateRate>
      <leftJoint>left_wheel_joint</leftJoint>
      <rightJoint>right_wheel_joint</rightJoint>
      <wheelSeparation>0.46</wheelSeparation>
      <wheelDiameter>0.1651</wheelDiameter>
      <wheelTorque>20</wheelTorque>
      <commandTopic>cmd_vel</commandTopic>
      <odometryTopic>odom</odometryTopic>
      <odometryFrame>odom</odometryFrame>
      <robotBaseFrame>base_footprint</robotBaseFrame>
      <!-- <rosDebugLevel>Debug</rosDebugLevel> -->
      <rosDebugLevel>na</rosDebugLevel>
      <publishWheelTF>false</publishWheelTF>
      <publishWheelJointState>false</publishWheelJointState>
      <publishOdomTF>false</publishOdomTF>
      <wheelAcceleration>0</wheelAcceleration>
      <publishTf>1</publishTf>
      <odometrySource>encoder</odometrySource>
    </plugin>
    <plugin filename="libgazebo_ros_control.so" name="gazebo_ros_control">
      <!-- <robotNamespace>/eleven</robotNamespace> -->
      <robotParam>/robot_description</robotParam>
      <!-- <robotSimType>gazebo_ros_control/DefaultRobotHWSim</robotSimType> -->
    </plugin>
  </gazebo>
</robot>
